[2021-03-15 21:01:45,225] {scheduler_job.py:154} INFO - Started process (PID=6715) to work on /home/alunoigti/airflow/dags/treino04.py
[2021-03-15 21:01:45,229] {scheduler_job.py:1589} INFO - Processing file /home/alunoigti/airflow/dags/treino04.py for tasks to queue
[2021-03-15 21:01:45,236] {logging_mixin.py:112} INFO - [2021-03-15 21:01:45,236] {dagbag.py:417} INFO - Filling up the DagBag from /home/alunoigti/airflow/dags/treino04.py
[2021-03-15 21:01:46,288] {logging_mixin.py:112} INFO - [2021-03-15 21:01:46,280] {dagbag.py:315} ERROR - Failed to bag_dag: /home/alunoigti/airflow/dags/treino04.py
Traceback (most recent call last):
  File "/home/alunoigti/anaconda3/lib/python3.8/site-packages/croniter/croniter.py", line 118, in _alphaconv
    return cls.ALPHACONV[index][key.lower()]
KeyError: '*/'

During handling of the above exception, another exception occurred:

Traceback (most recent call last):
  File "/home/alunoigti/anaconda3/lib/python3.8/site-packages/airflow/models/dagbag.py", line 309, in process_file
    croniter(dag.normalized_schedule_interval)
  File "/home/alunoigti/anaconda3/lib/python3.8/site-packages/croniter/croniter.py", line 112, in __init__
    self.expanded, self.nth_weekday_of_month = self.expand(expr_format)
  File "/home/alunoigti/anaconda3/lib/python3.8/site-packages/croniter/croniter.py", line 590, in expand
    t = cls._alphaconv(i, t, expressions)
  File "/home/alunoigti/anaconda3/lib/python3.8/site-packages/croniter/croniter.py", line 120, in _alphaconv
    raise CroniterNotAlphaError(
croniter.croniter.CroniterNotAlphaError: [*/ * * * *] is not acceptable
[2021-03-15 21:01:46,288] {scheduler_job.py:1601} INFO - DAG(s) dict_keys(['treino-03']) retrieved from /home/alunoigti/airflow/dags/treino04.py
[2021-03-15 21:01:46,345] {scheduler_job.py:1305} INFO - Processing treino-03
[2021-03-15 21:01:46,363] {scheduler_job.py:167} ERROR - Got an exception! Propagating...
Traceback (most recent call last):
  File "/home/alunoigti/anaconda3/lib/python3.8/site-packages/croniter/croniter.py", line 118, in _alphaconv
    return cls.ALPHACONV[index][key.lower()]
KeyError: '*/'

During handling of the above exception, another exception occurred:

Traceback (most recent call last):
  File "/home/alunoigti/anaconda3/lib/python3.8/site-packages/airflow/jobs/scheduler_job.py", line 157, in _run_file_processor
    result = scheduler_job.process_file(file_path,
  File "/home/alunoigti/anaconda3/lib/python3.8/site-packages/airflow/utils/db.py", line 74, in wrapper
    return func(*args, **kwargs)
  File "/home/alunoigti/anaconda3/lib/python3.8/site-packages/airflow/jobs/scheduler_job.py", line 1637, in process_file
    self._process_dags(dagbag, dags, ti_keys_to_schedule)
  File "/home/alunoigti/anaconda3/lib/python3.8/site-packages/airflow/jobs/scheduler_job.py", line 1307, in _process_dags
    dag_run = self.create_dag_run(dag)
  File "/home/alunoigti/anaconda3/lib/python3.8/site-packages/airflow/utils/db.py", line 74, in wrapper
    return func(*args, **kwargs)
  File "/home/alunoigti/anaconda3/lib/python3.8/site-packages/airflow/jobs/scheduler_job.py", line 705, in create_dag_run
    next_run_date = dag.following_schedule(last_scheduled_run)
  File "/home/alunoigti/anaconda3/lib/python3.8/site-packages/airflow/models/dag.py", line 421, in following_schedule
    cron = croniter(self.normalized_schedule_interval, naive)
  File "/home/alunoigti/anaconda3/lib/python3.8/site-packages/croniter/croniter.py", line 112, in __init__
    self.expanded, self.nth_weekday_of_month = self.expand(expr_format)
  File "/home/alunoigti/anaconda3/lib/python3.8/site-packages/croniter/croniter.py", line 590, in expand
    t = cls._alphaconv(i, t, expressions)
  File "/home/alunoigti/anaconda3/lib/python3.8/site-packages/croniter/croniter.py", line 120, in _alphaconv
    raise CroniterNotAlphaError(
croniter.croniter.CroniterNotAlphaError: [*/ * * * *] is not acceptable
[2021-03-15 21:03:37,151] {scheduler_job.py:154} INFO - Started process (PID=7007) to work on /home/alunoigti/airflow/dags/treino04.py
[2021-03-15 21:03:37,161] {scheduler_job.py:1589} INFO - Processing file /home/alunoigti/airflow/dags/treino04.py for tasks to queue
[2021-03-15 21:03:37,167] {logging_mixin.py:112} INFO - [2021-03-15 21:03:37,167] {dagbag.py:417} INFO - Filling up the DagBag from /home/alunoigti/airflow/dags/treino04.py
[2021-03-15 21:03:38,015] {logging_mixin.py:112} INFO - [2021-03-15 21:03:38,014] {dagbag.py:315} ERROR - Failed to bag_dag: /home/alunoigti/airflow/dags/treino04.py
Traceback (most recent call last):
  File "/home/alunoigti/anaconda3/lib/python3.8/site-packages/croniter/croniter.py", line 118, in _alphaconv
    return cls.ALPHACONV[index][key.lower()]
KeyError: '*/'

During handling of the above exception, another exception occurred:

Traceback (most recent call last):
  File "/home/alunoigti/anaconda3/lib/python3.8/site-packages/airflow/models/dagbag.py", line 309, in process_file
    croniter(dag.normalized_schedule_interval)
  File "/home/alunoigti/anaconda3/lib/python3.8/site-packages/croniter/croniter.py", line 112, in __init__
    self.expanded, self.nth_weekday_of_month = self.expand(expr_format)
  File "/home/alunoigti/anaconda3/lib/python3.8/site-packages/croniter/croniter.py", line 590, in expand
    t = cls._alphaconv(i, t, expressions)
  File "/home/alunoigti/anaconda3/lib/python3.8/site-packages/croniter/croniter.py", line 120, in _alphaconv
    raise CroniterNotAlphaError(
croniter.croniter.CroniterNotAlphaError: [*/ * * * *] is not acceptable
[2021-03-15 21:03:38,016] {scheduler_job.py:1601} INFO - DAG(s) dict_keys(['treino-03']) retrieved from /home/alunoigti/airflow/dags/treino04.py
[2021-03-15 21:03:38,074] {scheduler_job.py:1305} INFO - Processing treino-03
[2021-03-15 21:03:38,094] {scheduler_job.py:167} ERROR - Got an exception! Propagating...
Traceback (most recent call last):
  File "/home/alunoigti/anaconda3/lib/python3.8/site-packages/croniter/croniter.py", line 118, in _alphaconv
    return cls.ALPHACONV[index][key.lower()]
KeyError: '*/'

During handling of the above exception, another exception occurred:

Traceback (most recent call last):
  File "/home/alunoigti/anaconda3/lib/python3.8/site-packages/airflow/jobs/scheduler_job.py", line 157, in _run_file_processor
    result = scheduler_job.process_file(file_path,
  File "/home/alunoigti/anaconda3/lib/python3.8/site-packages/airflow/utils/db.py", line 74, in wrapper
    return func(*args, **kwargs)
  File "/home/alunoigti/anaconda3/lib/python3.8/site-packages/airflow/jobs/scheduler_job.py", line 1637, in process_file
    self._process_dags(dagbag, dags, ti_keys_to_schedule)
  File "/home/alunoigti/anaconda3/lib/python3.8/site-packages/airflow/jobs/scheduler_job.py", line 1307, in _process_dags
    dag_run = self.create_dag_run(dag)
  File "/home/alunoigti/anaconda3/lib/python3.8/site-packages/airflow/utils/db.py", line 74, in wrapper
    return func(*args, **kwargs)
  File "/home/alunoigti/anaconda3/lib/python3.8/site-packages/airflow/jobs/scheduler_job.py", line 705, in create_dag_run
    next_run_date = dag.following_schedule(last_scheduled_run)
  File "/home/alunoigti/anaconda3/lib/python3.8/site-packages/airflow/models/dag.py", line 421, in following_schedule
    cron = croniter(self.normalized_schedule_interval, naive)
  File "/home/alunoigti/anaconda3/lib/python3.8/site-packages/croniter/croniter.py", line 112, in __init__
    self.expanded, self.nth_weekday_of_month = self.expand(expr_format)
  File "/home/alunoigti/anaconda3/lib/python3.8/site-packages/croniter/croniter.py", line 590, in expand
    t = cls._alphaconv(i, t, expressions)
  File "/home/alunoigti/anaconda3/lib/python3.8/site-packages/croniter/croniter.py", line 120, in _alphaconv
    raise CroniterNotAlphaError(
croniter.croniter.CroniterNotAlphaError: [*/ * * * *] is not acceptable
[2021-03-15 21:04:46,645] {scheduler_job.py:154} INFO - Started process (PID=7219) to work on /home/alunoigti/airflow/dags/treino04.py
[2021-03-15 21:04:46,650] {scheduler_job.py:1589} INFO - Processing file /home/alunoigti/airflow/dags/treino04.py for tasks to queue
[2021-03-15 21:04:46,651] {logging_mixin.py:112} INFO - [2021-03-15 21:04:46,651] {dagbag.py:417} INFO - Filling up the DagBag from /home/alunoigti/airflow/dags/treino04.py
[2021-03-15 21:04:46,944] {logging_mixin.py:112} INFO - [2021-03-15 21:04:46,943] {dagbag.py:315} ERROR - Failed to bag_dag: /home/alunoigti/airflow/dags/treino04.py
Traceback (most recent call last):
  File "/home/alunoigti/anaconda3/lib/python3.8/site-packages/croniter/croniter.py", line 118, in _alphaconv
    return cls.ALPHACONV[index][key.lower()]
KeyError: '*/'

During handling of the above exception, another exception occurred:

Traceback (most recent call last):
  File "/home/alunoigti/anaconda3/lib/python3.8/site-packages/airflow/models/dagbag.py", line 309, in process_file
    croniter(dag.normalized_schedule_interval)
  File "/home/alunoigti/anaconda3/lib/python3.8/site-packages/croniter/croniter.py", line 112, in __init__
    self.expanded, self.nth_weekday_of_month = self.expand(expr_format)
  File "/home/alunoigti/anaconda3/lib/python3.8/site-packages/croniter/croniter.py", line 590, in expand
    t = cls._alphaconv(i, t, expressions)
  File "/home/alunoigti/anaconda3/lib/python3.8/site-packages/croniter/croniter.py", line 120, in _alphaconv
    raise CroniterNotAlphaError(
croniter.croniter.CroniterNotAlphaError: [*/ * * * *] is not acceptable
[2021-03-15 21:04:46,945] {scheduler_job.py:1601} INFO - DAG(s) dict_keys(['treino-03']) retrieved from /home/alunoigti/airflow/dags/treino04.py
[2021-03-15 21:04:46,980] {scheduler_job.py:1305} INFO - Processing treino-03
[2021-03-15 21:04:46,987] {scheduler_job.py:167} ERROR - Got an exception! Propagating...
Traceback (most recent call last):
  File "/home/alunoigti/anaconda3/lib/python3.8/site-packages/croniter/croniter.py", line 118, in _alphaconv
    return cls.ALPHACONV[index][key.lower()]
KeyError: '*/'

During handling of the above exception, another exception occurred:

Traceback (most recent call last):
  File "/home/alunoigti/anaconda3/lib/python3.8/site-packages/airflow/jobs/scheduler_job.py", line 157, in _run_file_processor
    result = scheduler_job.process_file(file_path,
  File "/home/alunoigti/anaconda3/lib/python3.8/site-packages/airflow/utils/db.py", line 74, in wrapper
    return func(*args, **kwargs)
  File "/home/alunoigti/anaconda3/lib/python3.8/site-packages/airflow/jobs/scheduler_job.py", line 1637, in process_file
    self._process_dags(dagbag, dags, ti_keys_to_schedule)
  File "/home/alunoigti/anaconda3/lib/python3.8/site-packages/airflow/jobs/scheduler_job.py", line 1307, in _process_dags
    dag_run = self.create_dag_run(dag)
  File "/home/alunoigti/anaconda3/lib/python3.8/site-packages/airflow/utils/db.py", line 74, in wrapper
    return func(*args, **kwargs)
  File "/home/alunoigti/anaconda3/lib/python3.8/site-packages/airflow/jobs/scheduler_job.py", line 705, in create_dag_run
    next_run_date = dag.following_schedule(last_scheduled_run)
  File "/home/alunoigti/anaconda3/lib/python3.8/site-packages/airflow/models/dag.py", line 421, in following_schedule
    cron = croniter(self.normalized_schedule_interval, naive)
  File "/home/alunoigti/anaconda3/lib/python3.8/site-packages/croniter/croniter.py", line 112, in __init__
    self.expanded, self.nth_weekday_of_month = self.expand(expr_format)
  File "/home/alunoigti/anaconda3/lib/python3.8/site-packages/croniter/croniter.py", line 590, in expand
    t = cls._alphaconv(i, t, expressions)
  File "/home/alunoigti/anaconda3/lib/python3.8/site-packages/croniter/croniter.py", line 120, in _alphaconv
    raise CroniterNotAlphaError(
croniter.croniter.CroniterNotAlphaError: [*/ * * * *] is not acceptable
[2021-03-15 21:06:02,431] {scheduler_job.py:154} INFO - Started process (PID=7459) to work on /home/alunoigti/airflow/dags/treino04.py
[2021-03-15 21:06:02,441] {scheduler_job.py:1589} INFO - Processing file /home/alunoigti/airflow/dags/treino04.py for tasks to queue
[2021-03-15 21:06:02,442] {logging_mixin.py:112} INFO - [2021-03-15 21:06:02,442] {dagbag.py:417} INFO - Filling up the DagBag from /home/alunoigti/airflow/dags/treino04.py
[2021-03-15 21:06:02,846] {logging_mixin.py:112} INFO - [2021-03-15 21:06:02,846] {dagbag.py:315} ERROR - Failed to bag_dag: /home/alunoigti/airflow/dags/treino04.py
Traceback (most recent call last):
  File "/home/alunoigti/anaconda3/lib/python3.8/site-packages/croniter/croniter.py", line 118, in _alphaconv
    return cls.ALPHACONV[index][key.lower()]
KeyError: '*/'

During handling of the above exception, another exception occurred:

Traceback (most recent call last):
  File "/home/alunoigti/anaconda3/lib/python3.8/site-packages/airflow/models/dagbag.py", line 309, in process_file
    croniter(dag.normalized_schedule_interval)
  File "/home/alunoigti/anaconda3/lib/python3.8/site-packages/croniter/croniter.py", line 112, in __init__
    self.expanded, self.nth_weekday_of_month = self.expand(expr_format)
  File "/home/alunoigti/anaconda3/lib/python3.8/site-packages/croniter/croniter.py", line 590, in expand
    t = cls._alphaconv(i, t, expressions)
  File "/home/alunoigti/anaconda3/lib/python3.8/site-packages/croniter/croniter.py", line 120, in _alphaconv
    raise CroniterNotAlphaError(
croniter.croniter.CroniterNotAlphaError: [*/ * * * *] is not acceptable
[2021-03-15 21:06:02,847] {scheduler_job.py:1601} INFO - DAG(s) dict_keys(['treino-03']) retrieved from /home/alunoigti/airflow/dags/treino04.py
[2021-03-15 21:06:02,901] {scheduler_job.py:1305} INFO - Processing treino-03
[2021-03-15 21:06:02,914] {scheduler_job.py:167} ERROR - Got an exception! Propagating...
Traceback (most recent call last):
  File "/home/alunoigti/anaconda3/lib/python3.8/site-packages/croniter/croniter.py", line 118, in _alphaconv
    return cls.ALPHACONV[index][key.lower()]
KeyError: '*/'

During handling of the above exception, another exception occurred:

Traceback (most recent call last):
  File "/home/alunoigti/anaconda3/lib/python3.8/site-packages/airflow/jobs/scheduler_job.py", line 157, in _run_file_processor
    result = scheduler_job.process_file(file_path,
  File "/home/alunoigti/anaconda3/lib/python3.8/site-packages/airflow/utils/db.py", line 74, in wrapper
    return func(*args, **kwargs)
  File "/home/alunoigti/anaconda3/lib/python3.8/site-packages/airflow/jobs/scheduler_job.py", line 1637, in process_file
    self._process_dags(dagbag, dags, ti_keys_to_schedule)
  File "/home/alunoigti/anaconda3/lib/python3.8/site-packages/airflow/jobs/scheduler_job.py", line 1307, in _process_dags
    dag_run = self.create_dag_run(dag)
  File "/home/alunoigti/anaconda3/lib/python3.8/site-packages/airflow/utils/db.py", line 74, in wrapper
    return func(*args, **kwargs)
  File "/home/alunoigti/anaconda3/lib/python3.8/site-packages/airflow/jobs/scheduler_job.py", line 705, in create_dag_run
    next_run_date = dag.following_schedule(last_scheduled_run)
  File "/home/alunoigti/anaconda3/lib/python3.8/site-packages/airflow/models/dag.py", line 421, in following_schedule
    cron = croniter(self.normalized_schedule_interval, naive)
  File "/home/alunoigti/anaconda3/lib/python3.8/site-packages/croniter/croniter.py", line 112, in __init__
    self.expanded, self.nth_weekday_of_month = self.expand(expr_format)
  File "/home/alunoigti/anaconda3/lib/python3.8/site-packages/croniter/croniter.py", line 590, in expand
    t = cls._alphaconv(i, t, expressions)
  File "/home/alunoigti/anaconda3/lib/python3.8/site-packages/croniter/croniter.py", line 120, in _alphaconv
    raise CroniterNotAlphaError(
croniter.croniter.CroniterNotAlphaError: [*/ * * * *] is not acceptable
[2021-03-15 21:07:27,064] {scheduler_job.py:154} INFO - Started process (PID=7561) to work on /home/alunoigti/airflow/dags/treino04.py
[2021-03-15 21:07:27,068] {scheduler_job.py:1589} INFO - Processing file /home/alunoigti/airflow/dags/treino04.py for tasks to queue
[2021-03-15 21:07:27,069] {logging_mixin.py:112} INFO - [2021-03-15 21:07:27,069] {dagbag.py:417} INFO - Filling up the DagBag from /home/alunoigti/airflow/dags/treino04.py
[2021-03-15 21:07:27,356] {logging_mixin.py:112} INFO - [2021-03-15 21:07:27,354] {dagbag.py:315} ERROR - Failed to bag_dag: /home/alunoigti/airflow/dags/treino04.py
Traceback (most recent call last):
  File "/home/alunoigti/anaconda3/lib/python3.8/site-packages/croniter/croniter.py", line 118, in _alphaconv
    return cls.ALPHACONV[index][key.lower()]
KeyError: '*/'

During handling of the above exception, another exception occurred:

Traceback (most recent call last):
  File "/home/alunoigti/anaconda3/lib/python3.8/site-packages/airflow/models/dagbag.py", line 309, in process_file
    croniter(dag.normalized_schedule_interval)
  File "/home/alunoigti/anaconda3/lib/python3.8/site-packages/croniter/croniter.py", line 112, in __init__
    self.expanded, self.nth_weekday_of_month = self.expand(expr_format)
  File "/home/alunoigti/anaconda3/lib/python3.8/site-packages/croniter/croniter.py", line 590, in expand
    t = cls._alphaconv(i, t, expressions)
  File "/home/alunoigti/anaconda3/lib/python3.8/site-packages/croniter/croniter.py", line 120, in _alphaconv
    raise CroniterNotAlphaError(
croniter.croniter.CroniterNotAlphaError: [*/ * * * *] is not acceptable
[2021-03-15 21:07:27,357] {scheduler_job.py:1601} INFO - DAG(s) dict_keys(['treino-03']) retrieved from /home/alunoigti/airflow/dags/treino04.py
[2021-03-15 21:07:27,395] {scheduler_job.py:1305} INFO - Processing treino-03
[2021-03-15 21:07:27,402] {scheduler_job.py:167} ERROR - Got an exception! Propagating...
Traceback (most recent call last):
  File "/home/alunoigti/anaconda3/lib/python3.8/site-packages/croniter/croniter.py", line 118, in _alphaconv
    return cls.ALPHACONV[index][key.lower()]
KeyError: '*/'

During handling of the above exception, another exception occurred:

Traceback (most recent call last):
  File "/home/alunoigti/anaconda3/lib/python3.8/site-packages/airflow/jobs/scheduler_job.py", line 157, in _run_file_processor
    result = scheduler_job.process_file(file_path,
  File "/home/alunoigti/anaconda3/lib/python3.8/site-packages/airflow/utils/db.py", line 74, in wrapper
    return func(*args, **kwargs)
  File "/home/alunoigti/anaconda3/lib/python3.8/site-packages/airflow/jobs/scheduler_job.py", line 1637, in process_file
    self._process_dags(dagbag, dags, ti_keys_to_schedule)
  File "/home/alunoigti/anaconda3/lib/python3.8/site-packages/airflow/jobs/scheduler_job.py", line 1307, in _process_dags
    dag_run = self.create_dag_run(dag)
  File "/home/alunoigti/anaconda3/lib/python3.8/site-packages/airflow/utils/db.py", line 74, in wrapper
    return func(*args, **kwargs)
  File "/home/alunoigti/anaconda3/lib/python3.8/site-packages/airflow/jobs/scheduler_job.py", line 705, in create_dag_run
    next_run_date = dag.following_schedule(last_scheduled_run)
  File "/home/alunoigti/anaconda3/lib/python3.8/site-packages/airflow/models/dag.py", line 421, in following_schedule
    cron = croniter(self.normalized_schedule_interval, naive)
  File "/home/alunoigti/anaconda3/lib/python3.8/site-packages/croniter/croniter.py", line 112, in __init__
    self.expanded, self.nth_weekday_of_month = self.expand(expr_format)
  File "/home/alunoigti/anaconda3/lib/python3.8/site-packages/croniter/croniter.py", line 590, in expand
    t = cls._alphaconv(i, t, expressions)
  File "/home/alunoigti/anaconda3/lib/python3.8/site-packages/croniter/croniter.py", line 120, in _alphaconv
    raise CroniterNotAlphaError(
croniter.croniter.CroniterNotAlphaError: [*/ * * * *] is not acceptable
[2021-03-15 21:08:38,073] {scheduler_job.py:154} INFO - Started process (PID=7809) to work on /home/alunoigti/airflow/dags/treino04.py
[2021-03-15 21:08:38,082] {scheduler_job.py:1589} INFO - Processing file /home/alunoigti/airflow/dags/treino04.py for tasks to queue
[2021-03-15 21:08:38,083] {logging_mixin.py:112} INFO - [2021-03-15 21:08:38,083] {dagbag.py:417} INFO - Filling up the DagBag from /home/alunoigti/airflow/dags/treino04.py
[2021-03-15 21:08:38,875] {logging_mixin.py:112} INFO - [2021-03-15 21:08:38,874] {dagbag.py:315} ERROR - Failed to bag_dag: /home/alunoigti/airflow/dags/treino04.py
Traceback (most recent call last):
  File "/home/alunoigti/anaconda3/lib/python3.8/site-packages/croniter/croniter.py", line 118, in _alphaconv
    return cls.ALPHACONV[index][key.lower()]
KeyError: '*/'

During handling of the above exception, another exception occurred:

Traceback (most recent call last):
  File "/home/alunoigti/anaconda3/lib/python3.8/site-packages/airflow/models/dagbag.py", line 309, in process_file
    croniter(dag.normalized_schedule_interval)
  File "/home/alunoigti/anaconda3/lib/python3.8/site-packages/croniter/croniter.py", line 112, in __init__
    self.expanded, self.nth_weekday_of_month = self.expand(expr_format)
  File "/home/alunoigti/anaconda3/lib/python3.8/site-packages/croniter/croniter.py", line 590, in expand
    t = cls._alphaconv(i, t, expressions)
  File "/home/alunoigti/anaconda3/lib/python3.8/site-packages/croniter/croniter.py", line 120, in _alphaconv
    raise CroniterNotAlphaError(
croniter.croniter.CroniterNotAlphaError: [*/ * * * *] is not acceptable
[2021-03-15 21:08:38,877] {scheduler_job.py:1601} INFO - DAG(s) dict_keys(['treino-03']) retrieved from /home/alunoigti/airflow/dags/treino04.py
[2021-03-15 21:08:38,917] {scheduler_job.py:1305} INFO - Processing treino-03
[2021-03-15 21:08:39,007] {scheduler_job.py:167} ERROR - Got an exception! Propagating...
Traceback (most recent call last):
  File "/home/alunoigti/anaconda3/lib/python3.8/site-packages/croniter/croniter.py", line 118, in _alphaconv
    return cls.ALPHACONV[index][key.lower()]
KeyError: '*/'

During handling of the above exception, another exception occurred:

Traceback (most recent call last):
  File "/home/alunoigti/anaconda3/lib/python3.8/site-packages/airflow/jobs/scheduler_job.py", line 157, in _run_file_processor
    result = scheduler_job.process_file(file_path,
  File "/home/alunoigti/anaconda3/lib/python3.8/site-packages/airflow/utils/db.py", line 74, in wrapper
    return func(*args, **kwargs)
  File "/home/alunoigti/anaconda3/lib/python3.8/site-packages/airflow/jobs/scheduler_job.py", line 1637, in process_file
    self._process_dags(dagbag, dags, ti_keys_to_schedule)
  File "/home/alunoigti/anaconda3/lib/python3.8/site-packages/airflow/jobs/scheduler_job.py", line 1307, in _process_dags
    dag_run = self.create_dag_run(dag)
  File "/home/alunoigti/anaconda3/lib/python3.8/site-packages/airflow/utils/db.py", line 74, in wrapper
    return func(*args, **kwargs)
  File "/home/alunoigti/anaconda3/lib/python3.8/site-packages/airflow/jobs/scheduler_job.py", line 705, in create_dag_run
    next_run_date = dag.following_schedule(last_scheduled_run)
  File "/home/alunoigti/anaconda3/lib/python3.8/site-packages/airflow/models/dag.py", line 421, in following_schedule
    cron = croniter(self.normalized_schedule_interval, naive)
  File "/home/alunoigti/anaconda3/lib/python3.8/site-packages/croniter/croniter.py", line 112, in __init__
    self.expanded, self.nth_weekday_of_month = self.expand(expr_format)
  File "/home/alunoigti/anaconda3/lib/python3.8/site-packages/croniter/croniter.py", line 590, in expand
    t = cls._alphaconv(i, t, expressions)
  File "/home/alunoigti/anaconda3/lib/python3.8/site-packages/croniter/croniter.py", line 120, in _alphaconv
    raise CroniterNotAlphaError(
croniter.croniter.CroniterNotAlphaError: [*/ * * * *] is not acceptable
[2021-03-15 21:10:01,305] {scheduler_job.py:154} INFO - Started process (PID=8076) to work on /home/alunoigti/airflow/dags/treino04.py
[2021-03-15 21:10:01,318] {scheduler_job.py:1589} INFO - Processing file /home/alunoigti/airflow/dags/treino04.py for tasks to queue
[2021-03-15 21:10:01,323] {logging_mixin.py:112} INFO - [2021-03-15 21:10:01,323] {dagbag.py:417} INFO - Filling up the DagBag from /home/alunoigti/airflow/dags/treino04.py
[2021-03-15 21:10:02,306] {logging_mixin.py:112} INFO - [2021-03-15 21:10:02,301] {dagbag.py:315} ERROR - Failed to bag_dag: /home/alunoigti/airflow/dags/treino04.py
Traceback (most recent call last):
  File "/home/alunoigti/anaconda3/lib/python3.8/site-packages/croniter/croniter.py", line 118, in _alphaconv
    return cls.ALPHACONV[index][key.lower()]
KeyError: '*/'

During handling of the above exception, another exception occurred:

Traceback (most recent call last):
  File "/home/alunoigti/anaconda3/lib/python3.8/site-packages/airflow/models/dagbag.py", line 309, in process_file
    croniter(dag.normalized_schedule_interval)
  File "/home/alunoigti/anaconda3/lib/python3.8/site-packages/croniter/croniter.py", line 112, in __init__
    self.expanded, self.nth_weekday_of_month = self.expand(expr_format)
  File "/home/alunoigti/anaconda3/lib/python3.8/site-packages/croniter/croniter.py", line 590, in expand
    t = cls._alphaconv(i, t, expressions)
  File "/home/alunoigti/anaconda3/lib/python3.8/site-packages/croniter/croniter.py", line 120, in _alphaconv
    raise CroniterNotAlphaError(
croniter.croniter.CroniterNotAlphaError: [*/ * * * *] is not acceptable
[2021-03-15 21:10:02,307] {scheduler_job.py:1601} INFO - DAG(s) dict_keys(['treino-03']) retrieved from /home/alunoigti/airflow/dags/treino04.py
[2021-03-15 21:10:02,424] {scheduler_job.py:162} INFO - Processing /home/alunoigti/airflow/dags/treino04.py took 1.119 seconds
[2021-03-15 21:11:01,412] {scheduler_job.py:154} INFO - Started process (PID=8287) to work on /home/alunoigti/airflow/dags/treino04.py
[2021-03-15 21:11:01,436] {scheduler_job.py:1589} INFO - Processing file /home/alunoigti/airflow/dags/treino04.py for tasks to queue
[2021-03-15 21:11:01,439] {logging_mixin.py:112} INFO - [2021-03-15 21:11:01,439] {dagbag.py:417} INFO - Filling up the DagBag from /home/alunoigti/airflow/dags/treino04.py
[2021-03-15 21:11:02,825] {logging_mixin.py:112} INFO - [2021-03-15 21:11:02,822] {dagbag.py:315} ERROR - Failed to bag_dag: /home/alunoigti/airflow/dags/treino04.py
Traceback (most recent call last):
  File "/home/alunoigti/anaconda3/lib/python3.8/site-packages/croniter/croniter.py", line 118, in _alphaconv
    return cls.ALPHACONV[index][key.lower()]
KeyError: '*/'

During handling of the above exception, another exception occurred:

Traceback (most recent call last):
  File "/home/alunoigti/anaconda3/lib/python3.8/site-packages/airflow/models/dagbag.py", line 309, in process_file
    croniter(dag.normalized_schedule_interval)
  File "/home/alunoigti/anaconda3/lib/python3.8/site-packages/croniter/croniter.py", line 112, in __init__
    self.expanded, self.nth_weekday_of_month = self.expand(expr_format)
  File "/home/alunoigti/anaconda3/lib/python3.8/site-packages/croniter/croniter.py", line 590, in expand
    t = cls._alphaconv(i, t, expressions)
  File "/home/alunoigti/anaconda3/lib/python3.8/site-packages/croniter/croniter.py", line 120, in _alphaconv
    raise CroniterNotAlphaError(
croniter.croniter.CroniterNotAlphaError: [*/ * * * *] is not acceptable
[2021-03-15 21:11:02,826] {scheduler_job.py:1601} INFO - DAG(s) dict_keys(['treino-03']) retrieved from /home/alunoigti/airflow/dags/treino04.py
[2021-03-15 21:11:02,893] {scheduler_job.py:162} INFO - Processing /home/alunoigti/airflow/dags/treino04.py took 1.481 seconds
